Workbook

Sheet Input
B2: Valuation Date | C2: {{ValuationDate}}
B3: Issue Date | C3: {{IssueDate}}
B4: Principal | C4: {{Principal}} | D4: {{CurrencyUnit}}
B5: Conversion Securities | C5: Series B Preferred Membershup Units
B6: Conversion Price | C6: {{ConversionPrice}}
B7: Day Basis | C7: Actual/365
B8: Maturity Date | C8: {{MaturityDate}}
B9: Extended Maturity Date | C9: =EDATE(C8,12) -> #VALUE!
B10: Interest Rate | C10: {{InterestRate}}
B11: Prepayment | C11: May not be made without consent of Holder
B12: Conversion | C12: Prior to maturity date
B13: Probability for Extension | C13: 0.7
B15: Interest Payment Schedule (No Extension):
B16: {{FirstDatetoPay}} | C16: =C$4*$C$10*YEARFRAC(B16,$C$3,3) -> #VALUE!
B17: =EDATE(B16,12) -> #VALUE! | C17: =C$4*$C$10*YEARFRAC(B17,B16,3) -> #VALUE!
B18: =EDATE(B17,12) -> #VALUE! | C18: =C$4*$C$10*YEARFRAC(B18,B17,3) -> #VALUE!
B19: =C8 -> {{MaturityDate}} | C19: =C$4*$C$10*YEARFRAC(B19,B18,3) -> #VALUE!
B21: Interest Payment Schedule (Extension):
B22: =B16 -> {{FirstDatetoPay}} | C22: =C$4*$C$10*YEARFRAC(B22,$C$3,3) -> #VALUE!
B23: =B17 -> #VALUE! | C23: =C$4*$C$10*YEARFRAC(B23,B22,3) -> #VALUE!
B24: =B18 -> #VALUE! | C24: =C$4*$C$10*YEARFRAC(B24,B23,3) -> #VALUE!
B25: =EDATE(B24,12) -> #VALUE! | C25: =C$4*$C$10*YEARFRAC(B25,B24,3) -> #VALUE!
B26: =C9 -> #VALUE! | C26: =C$4*$C$10*YEARFRAC(B26,B25,3) -> #VALUE!

Sheet Summary
B2: Summary | C2: =Input!D4 -> {{CurrencyUnit}}
B3: Valuation Date | C3: =Input!C2 -> {{ValuationDate}}
B5: Results: | C5: No Extension Scenario
B6: Liability Component | C6: =Summary!C3 -> {{ValuationDate}}
B7: Conversion Component | C7: =C8-C6 -> #VALUE!
B8: Fair Value | C8: ='Full CB'!C37 -> #VALUE!
B10: Principal Outstanding | C10: ='Full CB'!C22 -> {{Principal}}
B11: Difference | C11: =(E8-C10) -> #VALUE!

Sheet Full CB
B2: Full CB | G2: Date | H2: =C5 -> {{IssueDate}} | I2: ='Straight Debt'!B14 -> {{FirstDatetoPay}} | J2: ='Straight Debt'!B15 -> #VALUE! | K2: ='Straight Debt'!B16 -> #VALUE! | L2: ='Straight Debt'!B17 -> {{MaturityDate}}
B3: Valuation Date | C3: =Summary!C3 -> {{ValuationDate}}
G4: Steps | K4: =ROUNDDOWN(YEARFRAC(K2,$C$3,3)/$C$30,0)+1 -> #VALUE! | L4: =C29 -> 100
B5: Issue Date | C5: =Input!C3 -> {{IssueDate}} | G5: Interest Payment | K5: =Input!C18 -> #VALUE! | L5: =Input!C19 -> #VALUE!
B6: Maturity Date | C6: =Input!C8 -> {{MaturityDate}}
B7: State Date of Conversion Period | C7: =C5 -> {{IssueDate}}
B8: End Date of Conversion Period | C8: =C6 -> {{MaturityDate}}
B9: Spot Price of Series B Preferred Membership Units | C9: {{SportPrice}}
B10: Strike Price (USD) | C10: =Input!C6 -> {{ConversionPrice}}
B11: Discount Rate (Annual) | C11: ='Straight Debt'!C10 -> 0
B12: Discount Rate (Cont.) | C12: =LN(1+C11) -> 0
B13: Risk-free Rate (Annual) | C13: ='Straight Debt'!C6 -> {{RiskFreeRate}}
B14: Risk-free Rate (Cont.) | C14: =LN(1+C13) -> #VALUE!
B15: Volatility | C15: {{Volatility}}
B16: Dividend Yield | C16: {{DividendYield}}
B17: Bond Life (year) | C17: =YEARFRAC(C3,C6,3) -> #VALUE!
B18: Redemption Premium (Maturity) | C18: 1
B19: Coupon | C19: 0.1
B20: Accrued Interest (USD) | C20: =C22*C19*YEARFRAC(C21,C3,3) -> #VALUE!
B21: Last Coupon Payment Date | C21: {{LastCouponPaymentDate}} | G21: 0 | H21: =IF( (COLUMN()-COLUMN($G$21)) <= $C$29, (COLUMN()-COLUMN($G$21)), "" ) -> 1 | I21: =IF( (COLUMN()-COLUMN($G$21)) <= $C$29, (COLUMN()-COLUMN($G$21)), "" ) -> 2 | J21: =IF( (COLUMN()-COLUMN($G$21)) <= $C$29, (COLUMN()-COLUMN($G$21)), "" ) -> 3 | K21: =IF( (COLUMN()-COLUMN($G$21)) <= $C$29, (COLUMN()-COLUMN($G$21)), "" ) -> 4 | L21: =IF( (COLUMN()-COLUMN($G$21)) <= $C$29, (COLUMN()-COLUMN($G$21)), "" ) -> 5 | M21: =IF( (COLUMN()-COLUMN($G$21)) <= $C$29, (COLUMN()-COLUMN($G$21)), "" ) -> 6 | N21: =IF( (COLUMN()-COLUMN($G$21)) <= $C$29, (COLUMN()-COLUMN($G$21)), "" ) -> 7 | O21: =IF( (COLUMN()-COLUMN($G$21)) <= $C$29, (COLUMN()-COLUMN($G$21)), "" ) -> 8 | ... XFD21: =IF( (COLUMN()-COLUMN($G$21)) <= $C$29, (COLUMN()-COLUMN($G$21)), "" )
B22: Outstanding Principal of CB (USD) | C22: =Input!C4 -> {{Principal}} | E22: Date | G22: =$C$3 -> {{ValuationDate}} | H22: =$G$22+($C$6-$C$3)/$C$29*G21 -> #VALUE! | I22: =$G$22+($C$6-$C$3)/$C$29*I21 -> #VALUE! | J22: =$G$22+($C$6-$C$3)/$C$29*J21 -> #VALUE! | K22: =$G$22+($C$6-$C$3)/$C$29*K21 -> #VALUE! | L22: =$G$22+($C$6-$C$3)/$C$29*L21 -> #VALUE! | M22: =$G$22+($C$6-$C$3)/$C$29*M21 -> #VALUE! | N22: =$G$22+($C$6-$C$3)/$C$29*N21 -> #VALUE! | O22: =$G$22+($C$6-$C$3)/$C$29*O21 -> #VALUE! | P22: =$G$22+($C$6-$C$3)/$C$29*P21 -> #VALUE! | ... DC22: =$G$22+($C$6-$C$3)/$C$29*DC21 -> #VALUE!
B23: No. of Options | C23: =C22/C10 -> #VALUE! | E23: No. of Years | G23: =YEARFRAC($G$22,G22,0) -> #VALUE! | H23: =YEARFRAC($G$22,H22,0) -> #VALUE! | I23: =YEARFRAC($G$22,I22,0) -> #VALUE! | J23: =YEARFRAC($G$22,J22,0) -> #VALUE! | K23: =YEARFRAC($G$22,K22,0) -> #VALUE! | L23: =YEARFRAC($G$22,L22,0) -> #VALUE! | M23: =YEARFRAC($G$22,M22,0) -> #VALUE! | N23: =YEARFRAC($G$22,N22,0) -> #VALUE! | ... DC23: =YEARFRAC($G$22,DC22,0) -> #VALUE!
B24: Oustanding Number of Shares | C24: {{OustandingNumberofShares}}
B25: Total Principal Outstanding (USD) | C25: =C22 -> {{Principal}} | E25: Stock Price Binomial Tree | G25: =C9 -> {{SportPrice}} | H25: =G25*$C$32 -> #VALUE! | I25: =H25*$C$32 -> #VALUE! | J25: =I25*$C$32 -> #VALUE! | K25: =J25*$C$32 -> #VALUE! | L25: =K25*$C$32 -> #VALUE! | M25: =L25*$C$32 -> #VALUE! | N25: =M25*$C$32 -> #VALUE! | O25: =N25*$C$32 -> #VALUE! | ... DC25: =DB25*$C$32 -> #VALUE!
B26: Total No. of Shares to be Issued | C26: =C25/C10 -> #VALUE! | H26: =G25*$C$33 -> #VALUE! | I26: =G25*$C$32*$C$33 -> #VALUE! | J26: =H25*$C$32*$C$33 -> #VALUE! | K26: =I25*$C$32*$C$33 -> #VALUE! | L26: =J25*$C$32*$C$33 -> #VALUE! | M26: =K25*$C$32*$C$33 -> #VALUE! | N26: =L25*$C$32*$C$33 -> #VALUE! | O26: =M25*$C$32*$C$33 -> #VALUE! | P26: =N25*$C$32*$C$33 -> #VALUE! | ... DC26: =DA25*$C$32*$C$33 -> #VALUE!
B27: Dilution Effect | C27: {{DilutionEffect}} | I27: =H26*$C$33 -> #VALUE! | J27: =H26*$C$32*$C$33 -> #VALUE! | K27: =I26*$C$32*$C$33 -> #VALUE! | L27: =J26*$C$32*$C$33 -> #VALUE! | M27: =K26*$C$32*$C$33 -> #VALUE! | N27: =L26*$C$32*$C$33 -> #VALUE! | O27: =M26*$C$32*$C$33 -> #VALUE! | P27: =N26*$C$32*$C$33 -> #VALUE! | Q27: =O26*$C$32*$C$33 -> #VALUE! | ... DC27: =DA26*$C$32*$C$33 -> #VALUE!
J28: =I27*$C$33 -> #VALUE! | K28: =I27*$C$32*$C$33 -> #VALUE! | L28: =J27*$C$32*$C$33 -> #VALUE! | M28: =K27*$C$32*$C$33 -> #VALUE! | N28: =L27*$C$32*$C$33 -> #VALUE! | O28: =M27*$C$32*$C$33 -> #VALUE! | P28: =N27*$C$32*$C$33 -> #VALUE! | Q28: =O27*$C$32*$C$33 -> #VALUE! | R28: =P27*$C$32*$C$33 -> #VALUE! | ... DC28: =DA27*$C$32*$C$33 -> #VALUE!
B29: Steps | C29: 100 | K29: =J28*$C$33 -> #VALUE! | L29: =J28*$C$32*$C$33 -> #VALUE! | M29: =K28*$C$32*$C$33 -> #VALUE! | N29: =L28*$C$32*$C$33 -> #VALUE! | O29: =M28*$C$32*$C$33 -> #VALUE! | P29: =N28*$C$32*$C$33 -> #VALUE! | Q29: =O28*$C$32*$C$33 -> #VALUE! | R29: =P28*$C$32*$C$33 -> #VALUE! | S29: =Q28*$C$32*$C$33 -> #VALUE! | ... DC29: =DA28*$C$32*$C$33 -> #VALUE!
B30: Delta | C30: =C17/C29 -> #VALUE! | L30: =K29*$C$33 -> #VALUE! | M30: =K29*$C$32*$C$33 -> #VALUE! | N30: =L29*$C$32*$C$33 -> #VALUE! | O30: =M29*$C$32*$C$33 -> #VALUE! | P30: =N29*$C$32*$C$33 -> #VALUE! | Q30: =O29*$C$32*$C$33 -> #VALUE! | R30: =P29*$C$32*$C$33 -> #VALUE! | S30: =Q29*$C$32*$C$33 -> #VALUE! | T30: =R29*$C$32*$C$33 -> #VALUE! | ... DC30: =DA29*$C$32*$C$33 -> #VALUE!
M31: =L30*$C$33 -> #VALUE! | N31: =L30*$C$32*$C$33 -> #VALUE! | O31: =M30*$C$32*$C$33 -> #VALUE! | P31: =N30*$C$32*$C$33 -> #VALUE! | Q31: =O30*$C$32*$C$33 -> #VALUE! | R31: =P30*$C$32*$C$33 -> #VALUE! | S31: =Q30*$C$32*$C$33 -> #VALUE! | T31: =R30*$C$32*$C$33 -> #VALUE! | U31: =S30*$C$32*$C$33 -> #VALUE! | ... DC31: =DA30*$C$32*$C$33 -> #VALUE!
B32: U | C32: =EXP(C15*SQRT(C30)) -> #VALUE! | N32: =M31*$C$33 -> #VALUE! | O32: =M31*$C$32*$C$33 -> #VALUE! | P32: =N31*$C$32*$C$33 -> #VALUE! | Q32: =O31*$C$32*$C$33 -> #VALUE! | R32: =P31*$C$32*$C$33 -> #VALUE! | S32: =Q31*$C$32*$C$33 -> #VALUE! | T32: =R31*$C$32*$C$33 -> #VALUE! | U32: =S31*$C$32*$C$33 -> #VALUE! | V32: =T31*$C$32*$C$33 -> #VALUE! | ... DC32: =DA31*$C$32*$C$33 -> #VALUE!
B33: D | C33: =1/C32 -> #VALUE! | O33: =N32*$C$33 -> #VALUE! | P33: =N32*$C$32*$C$33 -> #VALUE! | Q33: =O32*$C$32*$C$33 -> #VALUE! | R33: =P32*$C$32*$C$33 -> #VALUE! | S33: =Q32*$C$32*$C$33 -> #VALUE! | T33: =R32*$C$32*$C$33 -> #VALUE! | U33: =S32*$C$32*$C$33 -> #VALUE! | V33: =T32*$C$32*$C$33 -> #VALUE! | W33: =U32*$C$32*$C$33 -> #VALUE! | ... DC33: =DA32*$C$32*$C$33 -> #VALUE!
B34: P | C34: =(EXP((C14-C16)*C30)-C33)/(C32-C33) -> #VALUE! | P34: =O33*$C$33 -> #VALUE! | Q34: =O33*$C$32*$C$33 -> #VALUE! | R34: =P33*$C$32*$C$33 -> #VALUE! | S34: =Q33*$C$32*$C$33 -> #VALUE! | T34: =R33*$C$32*$C$33 -> #VALUE! | U34: =S33*$C$32*$C$33 -> #VALUE! | V34: =T33*$C$32*$C$33 -> #VALUE! | W34: =U33*$C$32*$C$33 -> #VALUE! | X34: =V33*$C$32*$C$33 -> #VALUE! | ... DC34: =DA33*$C$32*$C$33 -> #VALUE!
B35: 1-P | C35: =1-C34 -> #VALUE! | Q35: =P34*$C$33 -> #VALUE! | R35: =P34*$C$32*$C$33 -> #VALUE! | S35: =Q34*$C$32*$C$33 -> #VALUE! | T35: =R34*$C$32*$C$33 -> #VALUE! | U35: =S34*$C$32*$C$33 -> #VALUE! | V35: =T34*$C$32*$C$33 -> #VALUE! | W35: =U34*$C$32*$C$33 -> #VALUE! | X35: =V34*$C$32*$C$33 -> #VALUE! | Y35: =W34*$C$32*$C$33 -> #VALUE! | ... DC35: =DA34*$C$32*$C$33 -> #VALUE!
R36: =Q35*$C$33 -> #VALUE! | S36: =Q35*$C$32*$C$33 -> #VALUE! | T36: =R35*$C$32*$C$33 -> #VALUE! | U36: =S35*$C$32*$C$33 -> #VALUE! | V36: =T35*$C$32*$C$33 -> #VALUE! | W36: =U35*$C$32*$C$33 -> #VALUE! | X36: =V35*$C$32*$C$33 -> #VALUE! | Y36: =W35*$C$32*$C$33 -> #VALUE! | Z36: =X35*$C$32*$C$33 -> #VALUE! | ... DC36: =DA35*$C$32*$C$33 -> #VALUE!
B37: Total CB Value (HK$) | C37: =ROUND(G238+G345,-4) -> #VALUE! | S37: =R36*$C$33 -> #VALUE! | T37: =R36*$C$32*$C$33 -> #VALUE! | U37: =S36*$C$32*$C$33 -> #VALUE! | V37: =T36*$C$32*$C$33 -> #VALUE! | W37: =U36*$C$32*$C$33 -> #VALUE! | X37: =V36*$C$32*$C$33 -> #VALUE! | Y37: =W36*$C$32*$C$33 -> #VALUE! | Z37: =X36*$C$32*$C$33 -> #VALUE! | AA37: =Y36*$C$32*$C$33 -> #VALUE! | ... DC37: =DA36*$C$32*$C$33 -> #VALUE!
T38: =S37*$C$33 -> #VALUE! | U38: =S37*$C$32*$C$33 -> #VALUE! | V38: =T37*$C$32*$C$33 -> #VALUE! | W38: =U37*$C$32*$C$33 -> #VALUE! | X38: =V37*$C$32*$C$33 -> #VALUE! | Y38: =W37*$C$32*$C$33 -> #VALUE! | Z38: =X37*$C$32*$C$33 -> #VALUE! | AA38: =Y37*$C$32*$C$33 -> #VALUE! | AB38: =Z37*$C$32*$C$33 -> #VALUE! | ... DC38: =DA37*$C$32*$C$33 -> #VALUE!
C39: =C37-C22 -> #VALUE! | U39: =T38*$C$33 -> #VALUE! | V39: =T38*$C$32*$C$33 -> #VALUE! | W39: =U38*$C$32*$C$33 -> #VALUE! | X39: =V38*$C$32*$C$33 -> #VALUE! | Y39: =W38*$C$32*$C$33 -> #VALUE! | Z39: =X38*$C$32*$C$33 -> #VALUE! | AA39: =Y38*$C$32*$C$33 -> #VALUE! | AB39: =Z38*$C$32*$C$33 -> #VALUE! | AC39: =AA38*$C$32*$C$33 -> #VALUE! | ... DC39: =DA38*$C$32*$C$33 -> #VALUE!
V40: =U39*$C$33 -> #VALUE! | W40: =U39*$C$32*$C$33 -> #VALUE! | X40: =V39*$C$32*$C$33 -> #VALUE! | Y40: =W39*$C$32*$C$33 -> #VALUE! | Z40: =X39*$C$32*$C$33 -> #VALUE! | AA40: =Y39*$C$32*$C$33 -> #VALUE! | AB40: =Z39*$C$32*$C$33 -> #VALUE! | AC40: =AA39*$C$32*$C$33 -> #VALUE! | AD40: =AB39*$C$32*$C$33 -> #VALUE! | ... DC40: =DA39*$C$32*$C$33 -> #VALUE!
W41: =V40*$C$33 -> #VALUE! | X41: =V40*$C$32*$C$33 -> #VALUE! | Y41: =W40*$C$32*$C$33 -> #VALUE! | Z41: =X40*$C$32*$C$33 -> #VALUE! | AA41: =Y40*$C$32*$C$33 -> #VALUE! | AB41: =Z40*$C$32*$C$33 -> #VALUE! | AC41: =AA40*$C$32*$C$33 -> #VALUE! | AD41: =AB40*$C$32*$C$33 -> #VALUE! | AE41: =AC40*$C$32*$C$33 -> #VALUE! | ... DC41: =DA40*$C$32*$C$33 -> #VALUE!
...

Sheet Straight Debt
B2: Straight Debt
B3: Valuation Date | C3: =Input!C2 -> {{ValuationDate}}
B5: Risky Rate:
B6: Rfr | C6: {{RiskFreeRate}}
B7: OAS | C7: {{CreditRiskPremium}}
B8: Liquidity | C8: {{LiquidityRiskPremium}}
B9: Other Risk | C9: {{OtherRisk}}
B10: Total | C10: =SUM(C6:C9) -> 0
B13: Date | C13: Interest Payment | D13: Principal Repayment | E13: TTM | F13: PV
B14: =Input!B16 -> {{FirstDatetoPay}}
B15: =Input!B17 -> #VALUE!
B16: =Input!B18 -> #VALUE! | C16: =Input!C18 -> #VALUE! | E16: =YEARFRAC(B16,$C$3,3) -> #VALUE! | F16: =SUM(C16:D16)/(1+$C$10)^E16 -> #VALUE!
B17: =Input!B19 -> {{MaturityDate}} | C17: =Input!C19 -> #VALUE! | D17: =Input!C4 -> {{Principal}} | E17: =YEARFRAC(B17,$C$3,3) -> #VALUE! | F17: =SUM(C17:D17)/(1+$C$10)^E17 -> #VALUE!
B18: Total PV | F18: =ROUND(SUM(F14:F17),-4) -> #VALUE!
D20: ß
