Workbook

Sheet Summary
B2: Summary | C2: USD
B3: Valuation Date | C3: =Input!C2 -> 45838
B5: Results: | C5: No Extension Scenario | D5: Exension Scenario | E5: Prob% Weighted Average
B6: Liability Component | C6: ='Straight Debt'!F18 -> 7780000 | D6: ='Straight Debt_Extend'!F19 -> 6050000 | E6: =C6*(1-Input!$C$13)+D6*Input!$C$13 -> 6569000
B7: Conversion Component | C7: =C8-C6 -> 0 | D7: =D8-D6 -> 10000 | E7: =C7*(1-Input!$C$13)+D7*Input!$C$13 -> 7000
B8: Fair Value | C8: ='Full CB'!C37 -> 7780000 | D8: ='Full CB_Extend'!C37 -> 6060000 | E8: =SUM(E6:E7) -> 6576000 | F8: <-- FV of the CB
B10: Principal Outstanding | C10: ='Full CB'!C22 -> 10000000
B11: Difference | C11: =(E8-C10) -> -3424000

Sheet Full CB
B2: Full CB | G2: Date | H2: =C5 -> 45121 | I2: {=TRANSPOSE(Input!B16:B19)} -> 45291 | J2: 45657 | K2: 46022 | L2: 46217
B3: Valuation Date | C3: =Input!C2 -> 45838
G4: Steps | I4: =MIN( IF(I2<C3, -1, ROUNDDOWN(YEARFRAC(I2, $C$3, 3)/$C$30, 0)+1), 100 ) -> -1 | J4: =MIN( IF(J2<C3, -1, ROUNDDOWN(YEARFRAC(J2, $C$3, 3)/$C$30, 0)+1), 100 ) -> -1 | K4: =MIN( IF(K2<C3, -1, ROUNDDOWN(YEARFRAC(K2, $C$3, 3)/$C$30, 0)+1), 100 ) -> 49 | L4: =MIN( IF(L2<C3, -1, ROUNDDOWN(YEARFRAC(L2, $C$3, 3)/$C$30, 0)+1), 100 ) -> 100 | M4: =MIN( IF(M2<C3, -1, ROUNDDOWN(YEARFRAC(M2, $C$3, 3)/$C$30, 0)+1), 100 ) -> -1 | N4: =MIN( IF(N2<C3, -1, ROUNDDOWN(YEARFRAC(N2, $C$3, 3)/$C$30, 0)+1), 100 ) -> -1 | O4: =MIN( IF(O2<C3, -1, ROUNDDOWN(YEARFRAC(O2, $C$3, 3)/$C$30, 0)+1), 100 ) -> -1
B5: Issue Date | C5: =Input!C3 -> 45121 | D5: =C5 -> 45121 | G5: Interest Payment | K5: =Input!C18 -> 1000000 | L5: =Input!C19 -> 534246.58
B6: Maturity Date | C6: =Input!C8 -> 46217 | D6: =C6 -> 46217
B7: State Date of Conversion Period | C7: =C5 -> 45121 | D7: =C7 -> 45121
B8: End Date of Conversion Period | C8: =C6 -> 46217 | D8: =C8 -> 46217
B9: Spot Price of Series B Preferred Membership Units | C9: 1226574 | D9: Based on allocation as at 2025/6/30
B10: Strike Price (USD) | C10: =Input!C6 -> 5484545.2
B11: Discount Rate (Annual) | C11: ='Risky Rate'!C7 -> 0.49075828
B12: Discount Rate (Cont.) | C12: =LN(1+C11) -> 0.39928491
B13: Risk-free Rate (Annual) | C13: ='Risky Rate'!C3 -> 0.039623726
B14: Risk-free Rate (Cont.) | C14: =LN(1+C13) -> 0.038858846
B15: Volatility | C15: =Vol!G14 -> 0.37833444
B16: Dividend Yield | C16: 0
B17: Bond Life (year) | C17: =YEARFRAC(C3,C6,3) -> 1.0383562
B18: Redemption Premium (Maturity) | C18: 1
B19: Coupon | C19: 0.1
B20: Accrued Interest (USD) | C20: =C22*C19*YEARFRAC(C21,C3,3) -> 495890.41
B21: Last Coupon Payment Date | C21: =DATE(2024,12,31) -> 45657 | G21: 0 | H21: 1 | I21: 2 | J21: 3 | K21: 4 | L21: 5 | M21: 6 | N21: 7 | O21: 8 | P21: 9 | Q21: 10 | R21: 11 | S21: 12 | T21: 13 | U21: 14 | V21: 15 | W21: 16 | X21: 17 | Y21: 18 | Z21: 19 | AA21: 20 | AB21: 21 | AC21: 22 | AD21: 23 | AE21: 24 | AF21: 25 | AG21: 26 | AH21: 27 | AI21: 28 | AJ21: 29 | AK21: 30 | AL21: 31 | AM21: 32 | AN21: 33 | AO21: 34 | AP21: 35 | AQ21: 36 | AR21: 37 | AS21: 38 | AT21: 39 | AU21: 40 | AV21: 41 | AW21: 42 | AX21: 43 | AY21: 44 | AZ21: 45 | BA21: 46 | BB21: 47 | BC21: 48 | BD21: 49 | BE21: 50 | BF21: 51 | BG21: 52 | BH21: 53 | BI21: 54 | BJ21: 55 | BK21: 56 | BL21: 57 | BM21: 58 | BN21: 59 | BO21: 60 | BP21: 61 | BQ21: 62 | BR21: 63 | BS21: 64 | BT21: 65 | BU21: 66 | BV21: 67 | BW21: 68 | BX21: 69 | BY21: 70 | BZ21: 71 | CA21: 72 | CB21: 73 | CC21: 74 | CD21: 75 | CE21: 76 | CF21: 77 | CG21: 78 | CH21: 79 | CI21: 80 | CJ21: 81 | CK21: 82 | CL21: 83 | CM21: 84 | CN21: 85 | CO21: 86 | CP21: 87 | CQ21: 88 | CR21: 89 | CS21: 90 | CT21: 91 | CU21: 92 | CV21: 93 | CW21: 94 | CX21: 95 | CY21: 96 | CZ21: 97 | DA21: 98 | DB21: 99 | DC21: 100
B22: Outstanding Principal of CB (USD) | C22: =Input!C4 -> 10000000 | E22: Date | G22: =$C$3 -> 45838 | H22: =$G$22+($C$6-$C$3)/$C$29*H21 -> 45841.79 | I22: =$G$22+($C$6-$C$3)/$C$29*I21 -> 45845.58 | J22: =$G$22+($C$6-$C$3)/$C$29*J21 -> 45849.37 | K22: =$G$22+($C$6-$C$3)/$C$29*K21 -> 45853.16 | L22: =$G$22+($C$6-$C$3)/$C$29*L21 -> 45856.95 | M22: =$G$22+($C$6-$C$3)/$C$29*M21 -> 45860.74 | N22: =$G$22+($C$6-$C$3)/$C$29*N21 -> 45864.53 | O22: =$G$22+($C$6-$C$3)/$C$29*O21 -> 45868.32 | ... DC22: =$G$22+($C$6-$C$3)/$C$29*DC21 -> 46217
B23: No. of Options | C23: =C22/C10 -> 1.8233052 | E23: No. of Years | G23: =YEARFRAC($G$22,G22,0) -> 0 | H23: =YEARFRAC($G$22,H22,0) -> 0.0083333333 | I23: =YEARFRAC($G$22,I22,0) -> 0.019444444 | J23: =YEARFRAC($G$22,J22,0) -> 0.030555556 | K23: =YEARFRAC($G$22,K22,0) -> 0.041666667 | L23: =YEARFRAC($G$22,L22,0) -> 0.05 | M23: =YEARFRAC($G$22,M22,0) -> 0.061111111 | N23: =YEARFRAC($G$22,N22,0) -> 0.072222222 | ... DC23: =YEARFRAC($G$22,DC22,0) -> 1.0388889
B24: Oustanding Number of Shares | C24: 68.773706
B25: Total Principal Outstanding (USD) | C25: =C22 -> 10000000 | E25: Stock Price Binomial Tree | G25: =C9 -> 1226574 | H25: =G25*$C$32 -> 1274784.5 | I25: =H25*$C$32 -> 1324889.9 | J25: =I25*$C$32 -> 1376964.6 | K25: =J25*$C$32 -> 1431086.2 | L25: =K25*$C$32 -> 1487335 | M25: =L25*$C$32 -> 1545794.6 | N25: =M25*$C$32 -> 1606552 | O25: =N25*$C$32 -> 1669697.5 | ... DC25: =DB25*$C$32 -> 57942084
B26: Total No. of Shares to be Issued | C26: =C25/C10 -> 1.8233052 | H26: =G25*$C$33 -> 1180186.8 | I26: =G25*$C$32*$C$33 -> 1226574 | J26: =H25*$C$32*$C$33 -> 1274784.5 | K26: =I25*$C$32*$C$33 -> 1324889.9 | L26: =J25*$C$32*$C$33 -> 1376964.6 | M26: =K25*$C$32*$C$33 -> 1431086.2 | N26: =L25*$C$32*$C$33 -> 1487335 | O26: =M25*$C$32*$C$33 -> 1545794.6 | P26: =N25*$C$32*$C$33 -> 1606552 | ... DC26: =DA25*$C$32*$C$33 -> 53642388
B27: Dilution Effect | C27: 1 | I27: =H26*$C$33 -> 1135553.9 | J27: =H26*$C$32*$C$33 -> 1180186.8 | K27: =I26*$C$32*$C$33 -> 1226574 | L27: =J26*$C$32*$C$33 -> 1274784.5 | M27: =K26*$C$32*$C$33 -> 1324889.9 | N27: =L26*$C$32*$C$33 -> 1376964.6 | O27: =M26*$C$32*$C$33 -> 1431086.2 | P27: =N26*$C$32*$C$33 -> 1487335 | Q27: =O26*$C$32*$C$33 -> 1545794.6 | ... DC27: =DA26*$C$32*$C$33 -> 49661759
J28: =I27*$C$33 -> 1092609 | K28: =I27*$C$32*$C$33 -> 1135553.9 | L28: =J27*$C$32*$C$33 -> 1180186.8 | M28: =K27*$C$32*$C$33 -> 1226574 | N28: =L27*$C$32*$C$33 -> 1274784.5 | O28: =M27*$C$32*$C$33 -> 1324889.9 | P28: =N27*$C$32*$C$33 -> 1376964.6 | Q28: =O27*$C$32*$C$33 -> 1431086.2 | R28: =P27*$C$32*$C$33 -> 1487335 | ... DC28: =DA27*$C$32*$C$33 -> 45976520
B29: Steps | C29: 100 | K29: =J28*$C$33 -> 1051288.1 | L29: =J28*$C$32*$C$33 -> 1092609 | M29: =K28*$C$32*$C$33 -> 1135553.9 | N29: =L28*$C$32*$C$33 -> 1180186.8 | O29: =M28*$C$32*$C$33 -> 1226574 | P29: =N28*$C$32*$C$33 -> 1274784.5 | Q29: =O28*$C$32*$C$33 -> 1324889.9 | R29: =P28*$C$32*$C$33 -> 1376964.6 | S29: =Q28*$C$32*$C$33 -> 1431086.2 | ... DC29: =DA28*$C$32*$C$33 -> 42564750
B30: Delta | C30: =C17/C29 -> 0.010383562 | L30: =K29*$C$33 -> 1011530 | M30: =K29*$C$32*$C$33 -> 1051288.1 | N30: =L29*$C$32*$C$33 -> 1092609 | O30: =M29*$C$32*$C$33 -> 1135553.9 | P30: =N29*$C$32*$C$33 -> 1180186.8 | Q30: =O29*$C$32*$C$33 -> 1226574 | R30: =P29*$C$32*$C$33 -> 1274784.5 | S30: =Q29*$C$32*$C$33 -> 1324889.9 | T30: =R29*$C$32*$C$33 -> 1376964.6 | ... DC30: =DA29*$C$32*$C$33 -> 39406157
M31: =L30*$C$33 -> 973275.41 | N31: =L30*$C$32*$C$33 -> 1011530 | O31: =M30*$C$32*$C$33 -> 1051288.1 | P31: =N30*$C$32*$C$33 -> 1092609 | Q31: =O30*$C$32*$C$33 -> 1135553.9 | R31: =P30*$C$32*$C$33 -> 1180186.8 | S31: =Q30*$C$32*$C$33 -> 1226574 | T31: =R30*$C$32*$C$33 -> 1274784.5 | U31: =S30*$C$32*$C$33 -> 1324889.9 | ... DC31: =DA30*$C$32*$C$33 -> 36481952
B32: U | C32: =EXP(C15*SQRT(C30)) -> 1.039305 | N32: =M31*$C$33 -> 936467.58 | O32: =M31*$C$32*$C$33 -> 973275.41 | P32: =N31*$C$32*$C$33 -> 1011530 | Q32: =O31*$C$32*$C$33 -> 1051288.1 | R32: =P31*$C$32*$C$33 -> 1092609 | S32: =Q31*$C$32*$C$33 -> 1135553.9 | T32: =R31*$C$32*$C$33 -> 1180186.8 | U32: =S31*$C$32*$C$33 -> 1226574 | V32: =T31*$C$32*$C$33 -> 1274784.5 | ... DC32: =DA31*$C$32*$C$33 -> 33774744
B33: D | C33: =1/C32 -> 0.96218149 | O33: =N32*$C$33 -> 901051.77 | P33: =N32*$C$32*$C$33 -> 936467.58 | Q33: =O32*$C$32*$C$33 -> 973275.41 | R33: =P32*$C$32*$C$33 -> 1011530 | S33: =Q32*$C$32*$C$33 -> 1051288.1 | T33: =R32*$C$32*$C$33 -> 1092609 | U33: =S32*$C$32*$C$33 -> 1135553.9 | V33: =T32*$C$32*$C$33 -> 1180186.8 | W33: =U32*$C$32*$C$33 -> 1226574 | ... DC33: =DA32*$C$32*$C$33 -> 31268429
B34: P | C34: =(EXP((C14-C16)*C30)-C33)/(C32-C33) -> 0.49559598 | P34: =O33*$C$33 -> 866975.33 | Q34: =O33*$C$32*$C$33 -> 901051.77 | R34: =P33*$C$32*$C$33 -> 936467.58 | S34: =Q33*$C$32*$C$33 -> 973275.41 | T34: =R33*$C$32*$C$33 -> 1011530 | U34: =S33*$C$32*$C$33 -> 1051288.1 | V34: =T33*$C$32*$C$33 -> 1092609 | W34: =U33*$C$32*$C$33 -> 1135553.9 | X34: =V33*$C$32*$C$33 -> 1180186.8 | ... DC34: =DA33*$C$32*$C$33 -> 28948099
B35: 1-P | C35: =1-C34 -> 0.50440402 | Q35: =P34*$C$33 -> 834187.61 | R35: =P34*$C$32*$C$33 -> 866975.33 | S35: =Q34*$C$32*$C$33 -> 901051.77 | T35: =R34*$C$32*$C$33 -> 936467.58 | U35: =S34*$C$32*$C$33 -> 973275.41 | V35: =T34*$C$32*$C$33 -> 1011530 | W35: =U34*$C$32*$C$33 -> 1051288.1 | X35: =V34*$C$32*$C$33 -> 1092609 | Y35: =W34*$C$32*$C$33 -> 1135553.9 | ... DC35: =DA34*$C$32*$C$33 -> 26799954
R36: =Q35*$C$33 -> 802639.88 | S36: =Q35*$C$32*$C$33 -> 834187.61 | T36: =R35*$C$32*$C$33 -> 866975.33 | U36: =S35*$C$32*$C$33 -> 901051.77 | V36: =T35*$C$32*$C$33 -> 936467.58 | W36: =U35*$C$32*$C$33 -> 973275.41 | X36: =V35*$C$32*$C$33 -> 1011530 | Y36: =W35*$C$32*$C$33 -> 1051288.1 | Z36: =X35*$C$32*$C$33 -> 1092609 | ... DC36: =DA35*$C$32*$C$33 -> 24811215
B37: Total CB Value (HK$) | C37: =ROUND(G238+G345,-4) -> 7780000 | S37: =R36*$C$33 -> 772285.23 | T37: =R36*$C$32*$C$33 -> 802639.88 | U37: =S36*$C$32*$C$33 -> 834187.61 | V37: =T36*$C$32*$C$33 -> 866975.33 | W37: =U36*$C$32*$C$33 -> 901051.77 | X37: =V36*$C$32*$C$33 -> 936467.58 | Y37: =W36*$C$32*$C$33 -> 973275.41 | Z37: =X36*$C$32*$C$33 -> 1011530 | AA37: =Y36*$C$32*$C$33 -> 1051288.1 | ... DC37: =DA36*$C$32*$C$33 -> 22970055
T38: =S37*$C$33 -> 743078.55 | U38: =S37*$C$32*$C$33 -> 772285.23 | V38: =T37*$C$32*$C$33 -> 802639.88 | W38: =U37*$C$32*$C$33 -> 834187.61 | X38: =V37*$C$32*$C$33 -> 866975.33 | Y38: =W37*$C$32*$C$33 -> 901051.77 | Z38: =X37*$C$32*$C$33 -> 936467.58 | AA38: =Y37*$C$32*$C$33 -> 973275.41 | AB38: =Z37*$C$32*$C$33 -> 1011530 | ... DC38: =DA37*$C$32*$C$33 -> 21265521
C39: =C37-C22 -> -2220000 | U39: =T38*$C$33 -> 714976.43 | V39: =T38*$C$32*$C$33 -> 743078.55 | W39: =U38*$C$32*$C$33 -> 772285.23 | X39: =V38*$C$32*$C$33 -> 802639.88 | Y39: =W38*$C$32*$C$33 -> 834187.61 | Z39: =X38*$C$32*$C$33 -> 866975.33 | AA39: =Y38*$C$32*$C$33 -> 901051.77 | AB39: =Z38*$C$32*$C$33 -> 936467.58 | AC39: =AA38*$C$32*$C$33 -> 973275.41 | ... DC39: =DA38*$C$32*$C$33 -> 19687475
V40: =U39*$C$33 -> 687937.08 | W40: =U39*$C$32*$C$33 -> 714976.43 | X40: =V39*$C$32*$C$33 -> 743078.55 | Y40: =W39*$C$32*$C$33 -> 772285.23 | Z40: =X39*$C$32*$C$33 -> 802639.88 | AA40: =Y39*$C$32*$C$33 -> 834187.61 | AB40: =Z39*$C$32*$C$33 -> 866975.33 | AC40: =AA39*$C$32*$C$33 -> 901051.77 | AD40: =AB39*$C$32*$C$33 -> 936467.58 | ... DC40: =DA39*$C$32*$C$33 -> 18226531
W41: =V40*$C$33 -> 661920.32 | X41: =V40*$C$32*$C$33 -> 687937.08 | Y41: =W40*$C$32*$C$33 -> 714976.43 | Z41: =X40*$C$32*$C$33 -> 743078.55 | AA41: =Y40*$C$32*$C$33 -> 772285.23 | AB41: =Z40*$C$32*$C$33 -> 802639.88 | AC41: =AA40*$C$32*$C$33 -> 834187.61 | AD41: =AB40*$C$32*$C$33 -> 866975.33 | AE41: =AC40*$C$32*$C$33 -> 901051.77 | ... DC41: =DA40*$C$32*$C$33 -> 16873998
...

Sheet Straight Debt
B2: Straight Debt
B3: Valuation Date | C3: =Input!C2 -> 45838
B5: Risky Rate:
B6: ='Risky Rate'!B3 -> Rfr | C6: ='Risky Rate'!C3 -> 0.039623726
B7: ='Risky Rate'!B4 -> OAS | C7: ='Risky Rate'!C4 -> 0.14850175
B8: ='Risky Rate'!B5 -> Liquidity | C8: ='Risky Rate'!C5 -> 0.015
B9: ='Risky Rate'!B6 -> Other Risk | C9: ='Risky Rate'!C6 -> 0.28763281
B10: Total | C10: =SUM(C6:C9) -> 0.49075828
B13: Date | C13: Interest Payment | D13: Principal Repayment | E13: TTM | F13: PV
B14: =Input!B16 -> 45291
B15: =Input!B17 -> 45657
B16: =Input!B18 -> 46022 | C16: =Input!C18 -> 1000000 | E16: =YEARFRAC(B16,$C$3,3) -> 0.50410959 | F16: =SUM(C16:D16)/(1+$C$10)^E16 -> 817680.71
B17: =Input!B19 -> 46217 | C17: =Input!C19 -> 534246.58 | D17: =Input!C4 -> 10000000 | E17: =YEARFRAC(B17,$C$3,3) -> 1.0383562 | F17: =SUM(C17:D17)/(1+$C$10)^E17 -> 6958970.8
B18: Total PV | F18: =ROUND(SUM(F14:F17),-4) -> 7780000

Sheet Input
B2: Valuation Date | C2: =DATE(2025,6,30) -> 45838
B3: Issue Date | C3: =DATE(2023,7,14) -> 45121
B4: Principal | C4: 10000000 | D4: USD (4mil+6mil)
B5: Conversion Securities | C5: Series B Preferred Membershup Units
B6: Conversion Price | C6: 5484545.2 | D6: USD
B7: Day Basis | C7: Actual/365
B8: Maturity Date | C8: =EDATE(C3,36) -> 46217 | D8: May be extended by up to 12 months
B9: Extended Maturity Date | C9: =EDATE(C8,12) -> 46582
B10: Interest Rate | C10: 0.1 | D10: Payable annually in arrear on 31 Dec of each calendar year. All outstanding accrued interest (1 Jan 2026 to 14 July 2026) shall be payable on maturity date
B11: Prepayment | C11: May not be made without consent of Holder
B12: Conversion | C12: Prior to maturity date
B13: Probability for Extension | C13: 0.7 | D13: Assumed by the Client after discussion with the issuer
B15: Interest Payment Schedule (No Extension):
B16: =DATE(2023,12,31) -> 45291 | C16: =C$4*$C$10*YEARFRAC(B16,$C$3,3) -> 465753.42
B17: =EDATE(B16,12) -> 45657 | C17: =C$4*$C$10*YEARFRAC(B17,B16,3) -> 1002739.7
B18: =EDATE(B17,12) -> 46022 | C18: =C$4*$C$10*YEARFRAC(B18,B17,3) -> 1000000
B19: =C8 -> 46217 | C19: =C$4*$C$10*YEARFRAC(B19,B18,3) -> 534246.58
B21: Interest Payment Schedule (Extension):
B22: =B16 -> 45291 | C22: =C$4*$C$10*YEARFRAC(B22,$C$3,3) -> 465753.42
B23: =B17 -> 45657 | C23: =C$4*$C$10*YEARFRAC(B23,B22,3) -> 1002739.7
B24: =B18 -> 46022 | C24: =C$4*$C$10*YEARFRAC(B24,B23,3) -> 1000000
B25: =EDATE(B24,12) -> 46387 | C25: =C$4*$C$10*YEARFRAC(B25,B24,3) -> 1000000
B26: =C9 -> 46582 | C26: =C$4*$C$10*YEARFRAC(B26,B25,3) -> 534246.58

Sheet Full CB_Extend
B2: Full CB | G2: Date | H2: =C5 -> 45121 | I2: {=TRANSPOSE(Input!B22:B26)} -> 45291 | J2: 45657 | K2: 46022 | L2: 46387 | M2: 46582
B3: Valuation Date | C3: =Input!C2 -> 45838
G4: Steps | K4: =ROUNDDOWN(YEARFRAC(K2,$C$3,3)/$C$30,0)+1 -> 25 | L4: =ROUNDDOWN(YEARFRAC(L2,$C$3,3)/$C$30,0)+1 -> 74 | M4: =C29 -> 100
B5: Issue Date | C5: =Input!C3 -> 45121 | D5: =C5 -> 45121 | G5: Interest Payment | K5: =Input!C24 -> 1000000 | L5: =Input!C25 -> 1000000 | M5: =Input!C26 -> 534246.58
B6: Extended Maturity Date | C6: =Input!C9 -> 46582 | D6: =C6 -> 46582
B7: State Date of Conversion Period | C7: =C5 -> 45121 | D7: =C7 -> 45121
B8: End Date of Conversion Period | C8: =C6 -> 46582 | D8: =C8 -> 46582
B9: Spot Price of Series B Preferred Membership Units | C9: 1226574 | D9: Based on allocation as at 2025/6/30
B10: Strike Price (USD) | C10: =Input!C6 -> 5484545.2
B11: Discount Rate (Annual) | C11: ='Risky Rate'!D7 -> 0.48833267
B12: Discount Rate (Cont.) | C12: =LN(1+C11) -> 0.39765648
B13: Risk-free Rate (Annual) | C13: ='Risky Rate'!D3 -> 0.03719811
B14: Risk-free Rate (Cont.) | C14: =LN(1+C13) -> 0.036522952
B15: Volatility | C15: =Vol!G26 -> 0.36458111
B16: Dividend Yield | C16: 0
B17: Bond Life (year) | C17: =YEARFRAC(C3,C6,3) -> 2.0383562
B18: Redemption Premium (Maturity) | C18: 1
B19: Coupon | C19: 0.1
B20: Accrued Interest (USD) | C20: =C22*C19*YEARFRAC(C21,C3,3) -> 495890.41
B21: Last Coupon Payment Date | C21: =DATE(2024,12,31) -> 45657 | G21: 0 | H21: 1 | I21: 2 | J21: 3 | K21: 4 | L21: 5 | M21: 6 | N21: 7 | O21: 8 | P21: 9 | Q21: 10 | R21: 11 | S21: 12 | T21: 13 | U21: 14 | V21: 15 | W21: 16 | X21: 17 | Y21: 18 | Z21: 19 | AA21: 20 | AB21: 21 | AC21: 22 | AD21: 23 | AE21: 24 | AF21: 25 | AG21: 26 | AH21: 27 | AI21: 28 | AJ21: 29 | AK21: 30 | AL21: 31 | AM21: 32 | AN21: 33 | AO21: 34 | AP21: 35 | AQ21: 36 | AR21: 37 | AS21: 38 | AT21: 39 | AU21: 40 | AV21: 41 | AW21: 42 | AX21: 43 | AY21: 44 | AZ21: 45 | BA21: 46 | BB21: 47 | BC21: 48 | BD21: 49 | BE21: 50 | BF21: 51 | BG21: 52 | BH21: 53 | BI21: 54 | BJ21: 55 | BK21: 56 | BL21: 57 | BM21: 58 | BN21: 59 | BO21: 60 | BP21: 61 | BQ21: 62 | BR21: 63 | BS21: 64 | BT21: 65 | BU21: 66 | BV21: 67 | BW21: 68 | BX21: 69 | BY21: 70 | BZ21: 71 | CA21: 72 | CB21: 73 | CC21: 74 | CD21: 75 | CE21: 76 | CF21: 77 | CG21: 78 | CH21: 79 | CI21: 80 | CJ21: 81 | CK21: 82 | CL21: 83 | CM21: 84 | CN21: 85 | CO21: 86 | CP21: 87 | CQ21: 88 | CR21: 89 | CS21: 90 | CT21: 91 | CU21: 92 | CV21: 93 | CW21: 94 | CX21: 95 | CY21: 96 | CZ21: 97 | DA21: 98 | DB21: 99 | DC21: 100
B22: Outstanding Principal of CB (USD) | C22: =Input!C4 -> 10000000 | E22: Date | G22: =$C$3 -> 45838 | H22: =$G$22+($C$6-$C$3)/$C$29*H21 -> 45845.44 | I22: =$G$22+($C$6-$C$3)/$C$29*I21 -> 45852.88 | J22: =$G$22+($C$6-$C$3)/$C$29*J21 -> 45860.32 | K22: =$G$22+($C$6-$C$3)/$C$29*K21 -> 45867.76 | L22: =$G$22+($C$6-$C$3)/$C$29*L21 -> 45875.2 | M22: =$G$22+($C$6-$C$3)/$C$29*M21 -> 45882.64 | N22: =$G$22+($C$6-$C$3)/$C$29*N21 -> 45890.08 | O22: =$G$22+($C$6-$C$3)/$C$29*O21 -> 45897.52 | ... DC22: =$G$22+($C$6-$C$3)/$C$29*DC21 -> 46582
B23: No. of Options | C23: =C22/C10 -> 1.8233052 | E23: No. of Years | G23: =YEARFRAC($G$22,G22,0) -> 0 | H23: =YEARFRAC($G$22,H22,0) -> 0.019444444 | I23: =YEARFRAC($G$22,I22,0) -> 0.038888889 | J23: =YEARFRAC($G$22,J22,0) -> 0.061111111 | K23: =YEARFRAC($G$22,K22,0) -> 0.080555556 | L23: =YEARFRAC($G$22,L22,0) -> 0.1 | M23: =YEARFRAC($G$22,M22,0) -> 0.11944444 | N23: =YEARFRAC($G$22,N22,0) -> 0.14166667 | ... DC23: =YEARFRAC($G$22,DC22,0) -> 2.0388889
B24: Oustanding Number of Shares | C24: 68.773706
B25: Total Principal Outstanding (USD) | C25: =C22 -> 10000000 | E25: Stock Price Binomial Tree | G25: =C9 -> 1226574 | H25: =G25*$C$32 -> 1292110 | I25: =H25*$C$32 -> 1361147.6 | J25: =I25*$C$32 -> 1433873.9 | K25: =J25*$C$32 -> 1510485.9 | L25: =K25*$C$32 -> 1591191.4 | M25: =L25*$C$32 -> 1676208.9 | N25: =M25*$C$32 -> 1765768.9 | O25: =N25*$C$32 -> 1860114.2 | ... DC25: =DB25*$C$32 -> 2.234944e+08
B26: Total No. of Shares to be Issued | C26: =C25/C10 -> 1.8233052 | H26: =G25*$C$33 -> 1164362 | I26: =G25*$C$32*$C$33 -> 1226574 | J26: =H25*$C$32*$C$33 -> 1292110 | K26: =I25*$C$32*$C$33 -> 1361147.6 | L26: =J25*$C$32*$C$33 -> 1433873.9 | M26: =K25*$C$32*$C$33 -> 1510485.9 | N26: =L25*$C$32*$C$33 -> 1591191.4 | O26: =M25*$C$32*$C$33 -> 1676208.9 | P26: =N25*$C$32*$C$33 -> 1765768.9 | ... DC26: =DA25*$C$32*$C$33 -> 2.0139801e+08
B27: Dilution Effect | C27: 1 | I27: =H26*$C$33 -> 1105305.5 | J27: =H26*$C$32*$C$33 -> 1164362 | K27: =I26*$C$32*$C$33 -> 1226574 | L27: =J26*$C$32*$C$33 -> 1292110 | M27: =K26*$C$32*$C$33 -> 1361147.6 | N27: =L26*$C$32*$C$33 -> 1433873.9 | O27: =M26*$C$32*$C$33 -> 1510485.9 | P27: =N26*$C$32*$C$33 -> 1591191.4 | Q27: =O26*$C$32*$C$33 -> 1676208.9 | ... DC27: =DA26*$C$32*$C$33 -> 1.8148625e+08
J28: =I27*$C$33 -> 1049244.2 | K28: =I27*$C$32*$C$33 -> 1105305.5 | L28: =J27*$C$32*$C$33 -> 1164362 | M28: =K27*$C$32*$C$33 -> 1226574 | N28: =L27*$C$32*$C$33 -> 1292110 | O28: =M27*$C$32*$C$33 -> 1361147.6 | P28: =N27*$C$32*$C$33 -> 1433873.9 | Q28: =O27*$C$32*$C$33 -> 1510485.9 | R28: =P27*$C$32*$C$33 -> 1591191.4 | ... DC28: =DA27*$C$32*$C$33 -> 1.6354312e+08
B29: Steps | C29: 100 | K29: =J28*$C$33 -> 996026.41 | L29: =J28*$C$32*$C$33 -> 1049244.2 | M29: =K28*$C$32*$C$33 -> 1105305.5 | N29: =L28*$C$32*$C$33 -> 1164362 | O29: =M28*$C$32*$C$33 -> 1226574 | P29: =N28*$C$32*$C$33 -> 1292110 | Q29: =O28*$C$32*$C$33 -> 1361147.6 | R29: =P28*$C$32*$C$33 -> 1433873.9 | S29: =Q28*$C$32*$C$33 -> 1510485.9 | ... DC29: =DA28*$C$32*$C$33 -> 1.4737398e+08
B30: Delta | C30: =C17/C29 -> 0.020383562 | L30: =K29*$C$33 -> 945507.82 | M30: =K29*$C$32*$C$33 -> 996026.41 | N30: =L29*$C$32*$C$33 -> 1049244.2 | O30: =M29*$C$32*$C$33 -> 1105305.5 | P30: =N29*$C$32*$C$33 -> 1164362 | Q30: =O29*$C$32*$C$33 -> 1226574 | R30: =P29*$C$32*$C$33 -> 1292110 | S30: =Q29*$C$32*$C$33 -> 1361147.6 | T30: =R29*$C$32*$C$33 -> 1433873.9 | ... DC30: =DA29*$C$32*$C$33 -> 1.3280345e+08
M31: =L30*$C$33 -> 897551.54 | N31: =L30*$C$32*$C$33 -> 945507.82 | O31: =M30*$C$32*$C$33 -> 996026.41 | P31: =N30*$C$32*$C$33 -> 1049244.2 | Q31: =O30*$C$32*$C$33 -> 1105305.5 | R31: =P30*$C$32*$C$33 -> 1164362 | S31: =Q30*$C$32*$C$33 -> 1226574 | T31: =R30*$C$32*$C$33 -> 1292110 | U31: =S30*$C$32*$C$33 -> 1361147.6 | ... DC31: =DA30*$C$32*$C$33 -> 1.1967347e+08
B32: U | C32: =EXP(C15*SQRT(C30)) -> 1.0534301 | N32: =M31*$C$33 -> 852027.61 | O32: =M31*$C$32*$C$33 -> 897551.54 | P32: =N31*$C$32*$C$33 -> 945507.82 | Q32: =O31*$C$32*$C$33 -> 996026.41 | R32: =P31*$C$32*$C$33 -> 1049244.2 | S32: =Q31*$C$32*$C$33 -> 1105305.5 | T32: =R31*$C$32*$C$33 -> 1164362 | U32: =S31*$C$32*$C$33 -> 1226574 | V32: =T31*$C$32*$C$33 -> 1292110 | ... DC32: =DA31*$C$32*$C$33 -> 1.0784163e+08
B33: D | C33: =1/C32 -> 0.94927987 | O33: =N32*$C$33 -> 808812.66 | P33: =N32*$C$32*$C$33 -> 852027.61 | Q33: =O32*$C$32*$C$33 -> 897551.54 | R33: =P32*$C$32*$C$33 -> 945507.82 | S33: =Q32*$C$32*$C$33 -> 996026.41 | T33: =R32*$C$32*$C$33 -> 1049244.2 | U33: =S32*$C$32*$C$33 -> 1105305.5 | V33: =T32*$C$32*$C$33 -> 1164362 | W33: =U32*$C$32*$C$33 -> 1226574 | ... DC33: =DA32*$C$32*$C$33 -> 97179572
B34: P | C34: =(EXP((C14-C16)*C30)-C33)/(C32-C33) -> 0.49414071 | P34: =O33*$C$33 -> 767789.58 | Q34: =O33*$C$32*$C$33 -> 808812.66 | R34: =P33*$C$32*$C$33 -> 852027.61 | S34: =Q33*$C$32*$C$33 -> 897551.54 | T34: =R33*$C$32*$C$33 -> 945507.82 | U34: =S33*$C$32*$C$33 -> 996026.41 | V34: =T33*$C$32*$C$33 -> 1049244.2 | W34: =U33*$C$32*$C$33 -> 1105305.5 | X34: =V33*$C$32*$C$33 -> 1164362 | ... DC34: =DA33*$C$32*$C$33 -> 87571648
B35: 1-P | C35: =1-C34 -> 0.50585929 | Q35: =P34*$C$33 -> 728847.19 | R35: =P34*$C$32*$C$33 -> 767789.58 | S35: =Q34*$C$32*$C$33 -> 808812.66 | T35: =R34*$C$32*$C$33 -> 852027.61 | U35: =S34*$C$32*$C$33 -> 897551.54 | V35: =T34*$C$32*$C$33 -> 945507.82 | W35: =U34*$C$32*$C$33 -> 996026.41 | X35: =V34*$C$32*$C$33 -> 1049244.2 | Y35: =W34*$C$32*$C$33 -> 1105305.5 | ... DC35: =DA34*$C$32*$C$33 -> 78913638
R36: =Q35*$C$33 -> 691879.96 | S36: =Q35*$C$32*$C$33 -> 728847.19 | T36: =R35*$C$32*$C$33 -> 767789.58 | U36: =S35*$C$32*$C$33 -> 808812.66 | V36: =T35*$C$32*$C$33 -> 852027.61 | W36: =U35*$C$32*$C$33 -> 897551.54 | X36: =V35*$C$32*$C$33 -> 945507.82 | Y36: =W35*$C$32*$C$33 -> 996026.41 | Z36: =X35*$C$32*$C$33 -> 1049244.2 | ... DC36: =DA35*$C$32*$C$33 -> 71111626
B37: Total CB Value (HK$) | C37: =ROUND(G238+G345,-4) -> 6060000 | S37: =R36*$C$33 -> 656787.72 | T37: =R36*$C$32*$C$33 -> 691879.96 | U37: =S36*$C$32*$C$33 -> 728847.19 | V37: =T36*$C$32*$C$33 -> 767789.58 | W37: =U36*$C$32*$C$33 -> 808812.66 | X37: =V36*$C$32*$C$33 -> 852027.61 | Y37: =W36*$C$32*$C$33 -> 897551.54 | Z37: =X36*$C$32*$C$33 -> 945507.82 | AA37: =Y36*$C$32*$C$33 -> 996026.41 | ... DC37: =DA36*$C$32*$C$33 -> 64080981
T38: =S37*$C$33 -> 623475.36 | U38: =S37*$C$32*$C$33 -> 656787.72 | V38: =T37*$C$32*$C$33 -> 691879.96 | W38: =U37*$C$32*$C$33 -> 728847.19 | X38: =V37*$C$32*$C$33 -> 767789.58 | Y38: =W37*$C$32*$C$33 -> 808812.66 | Z38: =X37*$C$32*$C$33 -> 852027.61 | AA38: =Y37*$C$32*$C$33 -> 897551.54 | AB38: =Z37*$C$32*$C$33 -> 945507.82 | ... DC38: =DA37*$C$32*$C$33 -> 57745440
C39: =C37-C22 -> -3940000 | U39: =T38*$C$33 -> 591852.61 | V39: =T38*$C$32*$C$33 -> 623475.36 | W39: =U38*$C$32*$C$33 -> 656787.72 | X39: =V38*$C$32*$C$33 -> 691879.96 | Y39: =W38*$C$32*$C$33 -> 728847.19 | Z39: =X38*$C$32*$C$33 -> 767789.58 | AA39: =Y38*$C$32*$C$33 -> 808812.66 | AB39: =Z38*$C$32*$C$33 -> 852027.61 | AC39: =AA38*$C$32*$C$33 -> 897551.54 | ... DC39: =DA38*$C$32*$C$33 -> 52036279
V40: =U39*$C$33 -> 561833.77 | W40: =U39*$C$32*$C$33 -> 591852.61 | X40: =V39*$C$32*$C$33 -> 623475.36 | Y40: =W39*$C$32*$C$33 -> 656787.72 | Z40: =X39*$C$32*$C$33 -> 691879.96 | AA40: =Y39*$C$32*$C$33 -> 728847.19 | AB40: =Z39*$C$32*$C$33 -> 767789.58 | AC40: =AA39*$C$32*$C$33 -> 808812.66 | AD40: =AB39*$C$32*$C$33 -> 852027.61 | ... DC40: =DA39*$C$32*$C$33 -> 46891571
W41: =V40*$C$33 -> 533337.49 | X41: =V40*$C$32*$C$33 -> 561833.77 | Y41: =W40*$C$32*$C$33 -> 591852.61 | Z41: =X40*$C$32*$C$33 -> 623475.36 | AA41: =Y40*$C$32*$C$33 -> 656787.72 | AB41: =Z40*$C$32*$C$33 -> 691879.96 | AC41: =AA40*$C$32*$C$33 -> 728847.19 | AD41: =AB40*$C$32*$C$33 -> 767789.58 | AE41: =AC40*$C$32*$C$33 -> 808812.66 | ... DC41: =DA40*$C$32*$C$33 -> 42255507
...

Sheet Straight Debt_Extend
B2: Straight Debt
B3: Valuation Date | C3: =Input!C2 -> 45838
B5: Risky Rate:
B6: ='Risky Rate'!B3 -> Rfr | C6: ='Risky Rate'!D3 -> 0.03719811
B7: ='Risky Rate'!B4 -> OAS | C7: ='Risky Rate'!D4 -> 0.14850175
B8: ='Risky Rate'!B5 -> Liquidity | C8: ='Risky Rate'!D5 -> 0.015
B9: ='Risky Rate'!B6 -> Other Risk | C9: ='Risky Rate'!D6 -> 0.28763281
B10: Total | C10: =SUM(C6:C9) -> 0.48833267
B13: Date | C13: Interest Payment | D13: Principal Repayment | E13: TTM | F13: PV
B14: =Input!B22 -> 45291
B15: =Input!B23 -> 45657
B16: =Input!B24 -> 46022 | C16: =Input!C24 -> 1000000 | E16: =YEARFRAC(B16,$C$3,3) -> 0.50410959 | F16: =SUM(C16:D16)/(1+$C$10)^E16 -> 818352.22
B17: =Input!B25 -> 46387 | C17: =Input!C25 -> 1000000 | E17: =YEARFRAC(B17,$C$3,3) -> 1.5041096 | F17: =SUM(C17:D17)/(1+$C$10)^E17 -> 549844.97
B18: =Input!B26 -> 46582 | C18: =Input!C26 -> 534246.58 | D18: =Input!C4 -> 10000000 | E18: =YEARFRAC(B18,$C$3,3) -> 2.0383562 | F18: =SUM(C18:D18)/(1+$C$10)^E18 -> 4683595.1
B19: Total PV | F19: =ROUND(SUM(F14:F18),-4) -> 6050000

Sheet Risky Rate
C2: 1.04-Y | D2: 2.04-Y
B3: Rfr | C3: =J28 -> 0.039623726 | D3: =J29 -> 0.03719811
B4: OAS | C4: =J18%% -> 0.14850175 | D4: =C4 -> 0.14850175
B5: Liquidity | C5: 0.015 | D5: =C5 -> 0.015
B6: Other Risk | C6: 0.28763281 | D6: =C6 -> 0.28763281 | E6: Backsolved and calibrated by day-1 valuation to match the issue price
B7: Risky Rate | C7: =SUM(C3:C6) -> 0.49075828 | D7: =SUM(D3:D6) -> 0.48833267
B10: Ticker | C10: Issuer | F10: S&P Rating | G10: Moody's Rating | H10: Fitch Rating | I10: OAS (bps) | J10: Firm OAS (bps)
B11: BP2798786 Corp | C11: ACProducts Holdings Inc | F11: CCC- | G11: Ca | H11: N/A | I11: 2806.55 | J11: =I11 -> 2806.55
B12: ZO4200051 Corp | C12: Cornerstone Building Brands Inc | F12: CCC | G12: Caa2 | H12: N/A | I12: 1270.8 | J12: =AVERAGE(I12:I13) -> 928.45
B13: BM6056535 Corp | C13: CP Atlas Buyer Inc | F13: CCC- | G13: Caa2 | H13: N/A | I13: 586.1 | J13: =I13 -> 586.1
B14: ZB8403683 Corp | C14: Vestel Elektronik Sanayi ve Ticaret AS | F14: N/A | G14: Caa1 | H14: B- | I14: 1334.99 | J14: =I14 -> 1334.99
B15: BO2210397 Corp | C15: Victoria PLC | F15: CCC+ | G15: Caa1 | H15: B- | I15: 595.61 | J15: =AVERAGE(I15:I16) -> 2361.885
B16: BO4852279 Corp | C16: Victoria PLC | F16: CCC+ | G16: Caa1 | H16: B- | I16: 4128.16
B17: YW5767903 Corp | C17: Wilsonart LLC | F17: B- | G17: Caa2 | H17: N/A | I17: 892.13 | J17: =I17 -> 892.13
J18: =AVERAGE(J11:J17) -> 1485.0175
I24: Tenor | J24: Rfr
I25: 1 | J25: 0.03972
I26: 2 | J26: 0.03721
I27: 3 | J27: 0.0369
I28: ='Full CB'!C17 -> 1.0383562 | J28: =TREND(J25:J26,I25:I26,I28) -> 0.039623726
I29: ='Full CB_Extend'!C17 -> 2.0383562 | J29: =TREND(J26:J27,I26:I27,I29) -> 0.03719811

Sheet Vol
B2: Ticker | C2: Name | G2: 270-Day Vol | I2: ='Full CB'!C17*260 -> 269.9726
B3: 021240 KS Equity | C3: Coway Co Ltd | G3: 41.9
B4: 192400 KS Equity | C4: Cuckoo Holdings Co Ltd | G4: 30.008
B5: SCNP IJ Equity | C5: Selaras Citra Nusantara Perkasa PT | G5: 69.575
B6: CROMPTON IN Equity | C6: Crompton Greaves Consumer Electricals Ltd | H6: no air purifier in the product line (see website) as at 30 June 2025
B7: 000651 CH Equity | C7: Gree Electric Appliances Inc of Zhuhai | G7: 26.858
B8: 002032 CH Equity | C8: Zhejiang Supor Co Ltd | G8: 25.659
B9: 605117 CH Equity | C9: Ningbo Deye Technology Co Ltd | G9: 50.265
B10: 5909 JP Equity | C10: Corona Corp | G10: 21.418
B11: 5951 JP Equity | C11: Dainichi Co Ltd | G11: 21.501
B12: 300247 CH Equity | C12: Youngy Health Co Ltd | G12: 53.317
B13: 4609 TT Equity | C13: Airlux Electrical Co Ltd | H13: no air purifier in the product line (see website) as at 30 June 2025
B14: Average | G14: =AVERAGE(G3:G13)% -> 0.37833444
B16: Ticker | C16: Name | G16: 530-Day Vol | I16: ='Full CB_Extend'!C17*260 -> 529.9726
B17: 021240 KS Equity | C17: Coway Co Ltd | G17: 36.627
B18: 192400 KS Equity | C18: Cuckoo Holdings Co Ltd | G18: 30.953
B19: SCNP IJ Equity | C19: Selaras Citra Nusantara Perkasa PT | G19: 69.261
B20: 000651 CH Equity | C20: Gree Electric Appliances Inc of Zhuhai | G20: 25.856
B21: 002032 CH Equity | C21: Zhejiang Supor Co Ltd | G21: 26.673
B22: 605117 CH Equity | C22: Ningbo Deye Technology Co Ltd | G22: 53.41
B23: 5909 JP Equity | C23: Corona Corp | G23: 18.387
B24: 5951 JP Equity | C24: Dainichi Co Ltd | G24: 20.189
B25: 300247 CH Equity | C25: Youngy Health Co Ltd | G25: 46.767
B26: Average | G26: =AVERAGE(G17:G25)% -> 0.36458111

Sheet Credit Profile
A1: Ticker | B1: N/A
A2: Company Name | B2: Delos Living LLC
A3: Latest Fiscal Period | B3: =DATE(2024,12,31) -> 45657
A4: Currency | B4: USD
A5: Moody's Financial Metrics™ | B5: 2023 | C5: 2018
C6: 2020
A7: Ratio Analysis | M7: Advanced Scoring | P7: Simple Scoring
A8: No. | B8: Ratio | C8: Value | D8: Rating | E8: Score | M8: Rating | N8: Score | P8: Rating | Q8: Ref | R8: Score
A9: 1 | B9: Debt / EBITDA | C9: =C38/C29 -> -4.0066078 | D9: C | E9: =IFERROR(INDEX($R$9:$R$16,MATCH($D9,$P$9:$P$16,0)),"") -> 21 | M9: Aaa | N9: =N10-1 -> 1 | P9: Aaa | Q9: Aaa | R9: 1
A10: =A9+1 -> 2 | B10: EBITA / Interest Expense | C10: =C29/C33 -> -1.6899959 | D10: C | E10: =IFERROR(INDEX($R$9:$R$16,MATCH($D10,$P$9:$P$16,0)),"") -> 21 | M10: Aa1 | N10: =N11-1 -> 2 | P10: Aa | Q10: Aa2 | R10: 3
A11: =A10+1 -> 3 | B11: Revenue (in US$ billion) | C11: =C26 -> 0.035008 | D11: C | E11: =IFERROR(INDEX($R$9:$R$16,MATCH($D11,$P$9:$P$16,0)),"") -> 21 | M11: Aa2 | N11: =N12-1 -> 3 | P11: A | Q11: A2 | R11: 6
A12: =A11+1 -> 4 | B12: RCF / Net Debt | C12: =IF(C39<=0,"N/A",C48/C39) -> -0.42216435 | D12: #N/A | F12: Not available for Financial Metrics™ in 2023 | M12: Aa3 | N12: =N13-1 -> 4 | P12: Baa | Q12: Baa2 | R12: 9
A13: =A12+1 -> 5 | B13: EBITA Margin | C13: =C31/C27 -> -0.96946412 | D13: C | E13: =IFERROR(INDEX($R$9:$R$16,MATCH($D13,$P$9:$P$16,0)),"") -> 21 | M13: A1 | N13: =N14-1 -> 5 | P13: Ba | Q13: Ba2 | R13: 12
A14: =A13+1 -> 6 | B14: Operating Margin | C14: =C32/C27 -> -1.0335923 | D14: C | E14: =IFERROR(INDEX($R$9:$R$16,MATCH($D14,$P$9:$P$16,0)),"") -> 21 | M14: A2 | N14: =N15-1 -> 6 | P14: B | Q14: B2 | R14: 15
A15: =A14+1 -> 7 | B15: FFO / Debt | C15: =IF(C38<=0,"N/A",C44/C38) -> -0.39797229 | D15: C | E15: =IFERROR(INDEX($R$9:$R$16,MATCH($D15,$P$9:$P$16,0)),"") -> 21 | M15: A3 | N15: =N16-1 -> 7 | P15: Caa | Q15: Caa2 | R15: 18
A16: =A15+1 -> 8 | B16: (FFO + Int Exp) / Int Exp | C16: =IF(C33<=0,"N/A",(C44+C33)/C33) -> -1.6947303 | D16: C | E16: =IFERROR(INDEX($R$9:$R$16,MATCH($D16,$P$9:$P$16,0)),"") -> 21 | M16: Baa1 | N16: =N17-1 -> 8 | P16: C | Q16: C | R16: 21
A17: =A16+1 -> 9 | B17: EBITA / Average Assets | C17: =C31/AVERAGE(C35:D35) -> -0.639291 | D17: C | E17: =IFERROR(INDEX($R$9:$R$16,MATCH($D17,$P$9:$P$16,0)),"") -> 21 | M17: Baa2 | N17: =N18-1 -> 9
A18: =A17+1 -> 10 | B18: CAPEX / Depreciation Expense | C18: =C49/C30 -> 0.14467698 | D18: C | E18: =IFERROR(INDEX($R$9:$R$16,MATCH($D18,$P$9:$P$16,0)),"") -> 21 | M18: Baa3 | N18: =N19-1 -> 10
A19: =A18+1 -> 11 | B19: Revenue Volatility | C19: =_xlfn.STDEV.S(C28:G28) -> #DIV/0! | D19: #DIV/0! | E19: =IFERROR(INDEX($R$9:$R$16,MATCH($D19,$P$9:$P$16,0)),"") | M19: Ba1 | N19: =N20-1 -> 11
B20: Average | E20: =AVERAGE(E9:E19) -> 21 | M20: Ba2 | N20: =N21-1 -> 12
B21: Rating | E21: =INDEX($M$9:$M$29,MATCH(E20,$N$9:$N$29,1)) -> C | M21: Ba3 | N21: =N22-1 -> 13
M22: B1 | N22: =N23-1 -> 14
A23: Financial Data (in local currency million, unless specified; all figures are show positive to their nature) | M23: B2 | N23: =N24-1 -> 15
A24: Fin Stmt | B24: Year | C24: T | D24: T-1 | E24: T-2 | F24: T-3 | G24: T-4 | H24: T-5 | M24: B3 | N24: =N25-1 -> 16
C25: =YEAR(B3) -> 2024 | D25: =C25-1 -> 2023 | E25: =D25-1 -> 2022 | F25: =E25-1 -> 2021 | G25: =F25-1 -> 2020 | H25: =G25-1 -> 2019 | M25: Caa1 | N25: =N26-1 -> 17
A26: PL | B26: Revenue (in US$ billion) | C26: =C27/1000000000 -> 0.035008 | M26: Caa2 | N26: =N27-1 -> 18
A27: PL | B27: Revenue | C27: ='2024FS'!D2 -> 35008000 | M27: Caa3 | N27: =N28-1 -> 19
A28: Cal | B28: Revenue Growth | C28: =IFERROR(C27/D27-1,"") | D28: =IFERROR(D27/E27-1,"") | E28: =IFERROR(E27/F27-1,"") | F28: =IFERROR(F27/G27-1,"") | G28: =IFERROR(G27/H27-1,"") | M28: Ca | N28: =N29-1 -> 20
A29: PL | B29: EBITDA | C29: ='2024FS'!D12 -> -32840000 | M29: C | N29: 21
A30: PL | B30: Depreciation | C30: ='2024FS'!D11 -> 1099000 | I30: Expense: positive
A31: PL | B31: EBITA | C31: ='2024FS'!D10 -> -33939000
A32: PL | B32: Operating Income (EBIT) | C32: ='2024FS'!D8 -> -36184000
A33: PL | B33: Interest Expense | C33: ='2024FS'!D7 -> 19432000 | I33: Expense: positive
A34: BS | B34: Cash and Cash Equivalent | C34: =SUM('2024FS'!D18:D19) -> 7540000
A35: BS | B35: Assets | C35: ='2024FS'!D21 -> 38364000 | D35: ='2024FS'!D22 -> 67813000
A36: BS | B36: Short-Term Debt | C36: =-SUM('2024FS'!D24:D25) -> 13258000
A37: BS | B37: Long-Term Debt | C37: =-SUM('2024FS'!D26:D27) -> 118319000
A38: Cal | B38: Debt | C38: =C36+C37 -> 131577000
A39: Cal | B39: Net Debt | C39: =C36+C37-C34 -> 124037000
A40: BS | B40: Deferred Taxes | C40: 0
...

Sheet Info from Client->

Sheet 2024FS
C1: in USD'000 | D1: in USD
A2: Revenue | C2: 35008 | D2: =C2*1000 -> 35008000
A4: Net Profit | C4: -55708 | D4: =C4*1000 -> -55708000
A5: Add: Tax | C5: 92 | D5: =C5*1000 -> 92000
A6: EBT | C6: =SUM(C4:C5) -> -55616 | D6: =C6*1000 -> -55616000
A7: Add: Interest | C7: 19432 | D7: =C7*1000 -> 19432000
A8: EBIT | C8: =SUM(C6:C7) -> -36184 | D8: =C8*1000 -> -36184000
A9: Add: Amortisation | C9: 2245 | D9: =C9*1000 -> 2245000 | E9: Amortization of operating lease right of use assets
A10: EBITA | C10: =SUM(C8:C9) -> -33939 | D10: =C10*1000 -> -33939000
A11: Add: Depreciation | C11: 1099 | D11: =C11*1000 -> 1099000
A12: EBITDA | C12: =SUM(C10:C11) -> -32840 | D12: =C12*1000 -> -32840000
A18: Cash and cash equivalents | C18: 5715 | D18: =C18*1000 -> 5715000
A19: Restricted cash | C19: 1825 | D19: =C19*1000 -> 1825000
A21: Total Asset in 2024 | C21: 38364 | D21: =C21*1000 -> 38364000
A22: Total Asset in 2023 | C22: 67813 | D22: =C22*1000 -> 67813000
A24: Debt, current portion | C24: -11425 | D24: =C24*1000 -> -11425000
A25: Operating lease liabilities, current portion | C25: -1833 | D25: =C25*1000 -> -1833000
A26: Long term debt, net of current portion | C26: -106312 | D26: =C26*1000 -> -106312000
A27: Operating lease liabilities, net of current portion | C27: -12007 | D27: =C27*1000 -> -12007000
A29: Total NAV | C29: -583702 | D29: =C29*1000 -> -583702000
A31: Capex | C31: 159 | D31: =C31*1000 -> 159000
